<?xml version="1.0" ?>
<sdf version="1.7">
  <world name='wheelchair_demo'>
    <physics name="1ms" type="ignored">
      <max_step_size>0.001</max_step_size>
      <real_time_factor>1.0</real_time_factor>
    </physics>

    <plugin
      filename="libignition-gazebo-physics-system.so"
      name="ignition::gazebo::systems::Physics">
    </plugin>
    <plugin
      filename="libignition-gazebo-user-commands-system.so"
      name="ignition::gazebo::systems::UserCommands">
    </plugin>
    <plugin
      filename="libignition-gazebo-scene-broadcaster-system.so"
      name="ignition::gazebo::systems::SceneBroadcaster">
    </plugin>

    <gui fullscreen="0">
      <plugin filename="GzScene3D" name="3D View">
        <ignition-gui>
          <title>3D View</title>
          <property type="bool" key="showTitleBar">false</property>
          <property type="string" key="state">docked</property>
        </ignition-gui>

        <engine>ogre2</engine>
        <scene>scene</scene>
        <ambient_light>0.4 0.4 0.4</ambient_light>
        <background_color>0.8 0.8 0.8</background_color>
      </plugin>

      <plugin filename="WorldControl" name="World control">
        <ignition-gui>
          <title>World control</title>
          <property type="bool" key="showTitleBar">false</property>
          <property type="bool" key="resizable">false</property>
          <property type="double" key="height">72</property>
          <property type="double" key="width">121</property>
          <property type="double" key="z">1</property>

          <property type="string" key="state">floating</property>
          <anchors target="3D View">
            <line own="left" target="left"/>
            <line own="bottom" target="bottom"/>
          </anchors>
        </ignition-gui>

        <play_pause>true</play_pause>
        <step>true</step>
        <start_paused>true</start_paused>
        <service>/world/wheelchair_demo/control</service>
        <stats_topic>/world/wheelchair_demo/stats</stats_topic>
      </plugin>

      <plugin filename="WorldStats" name="World Stats">
        <ignition-gui>
          <title>World Stats</title>
          <property type="bool" key="showTitleBar">false</property>
          <property type="bool" key="resizable">false</property>
          <property type="double" key="height">110</property>
          <property type="double" key="width">290</property>
          <property type="double" key="z">1</property>

          <property type="string" key="state">floating</property>
          <anchors target="3D View">
            <line own="right" target="right"/>
            <line own="bottom" target="bottom"/>
          </anchors>
        </ignition-gui>

        <sim_time>true</sim_time>
        <real_time>true</real_time>
        <real_time_factor>true</real_time_factor>
        <iterations>true</iterations>
        <topic>/world/wheelchair_demo/stats</topic>
      </plugin>

      <plugin filename="EntityTree" name="Entity Tree">
      </plugin>
    </gui>

    <light type="directional" name="sun">
      <cast_shadows>true</cast_shadows>
      <pose>0 0 10 0 0 0</pose>
      <diffuse>0.8 0.8 0.8 1</diffuse>
      <specular>0.2 0.2 0.2 1</specular>
      <attenuation>
        <range>1000</range>
        <constant>0.9</constant>
        <linear>0.01</linear>
        <quadratic>0.001</quadratic>
      </attenuation>
      <direction>-0.5 0.1 -0.9</direction>
    </light>

    <model name="ground_plane">
            <static>true</static>
            <link name="link">
                <collision name="collision">
                <geometry>
                    <plane>
                    <normal>0 0 1</normal>
                    </plane>
                </geometry>
                </collision>
                <visual name="visual">
                <geometry>
                    <plane>
                    <normal>0 0 1</normal>
                    <size>100 100</size>
                    </plane>
                </geometry>
                <material>
                    <ambient>0.8 0.8 0.8 1</ambient>
                    <diffuse>0.8 0.8 0.8 1</diffuse>
                    <specular>0.8 0.8 0.8 1</specular>
                </material>
                </visual>
            </link>
    </model>

    <model name="wheelchair" canonical_link="chassis">
      <pose relative_to="world">0 0 0 0 0 0</pose>
      <link name="chassis">
        <pose relative_to="__model__">0.5 0 2 0 0 0</pose>
<!--        <inertial>-->
<!--            <mass>1.14395</mass>-->
<!--            <inertia>-->
<!--                <ixx>0.095329</ixx>-->
<!--                <ixy>0</ixy>-->
<!--                <ixz>0</ixz>-->
<!--                <iyy>0.381317</iyy>-->
<!--                <iyz>0</iyz>-->
<!--                <izz>0.476646</izz>-->
<!--            </inertia>-->
<!--        </inertial>-->
        <visual name='visual'>
            <geometry>
                <box>
                    <size>3.2 2.5 3.6</size>
                </box>
            </geometry>
            <material>
                <ambient>0.0 0.0 1.0 1</ambient>
                <diffuse>0.0 0.0 1.0 1</diffuse>
                <specular>0.0 0.0 1.0 1</specular>
            </material>
        </visual>
        <collision name='collision'>
            <geometry>
                <box>
                    <size>3.2 2.5 3.6</size>
                </box>
            </geometry>
        </collision>
      </link>
      <link name="left_wheel">
        <pose relative_to="chassis">0 1.3 -1.2 -1.5707 0 0</pose>
        <visual name='visual'>
            <geometry>
                <cylinder>
                    <radius>0.8</radius>
                    <length>0.4</length>
                </cylinder>
            </geometry>
            <material>
                <ambient>1.0 0.0 0.0 1</ambient>
                <diffuse>1.0 0.0 0.0 1</diffuse>
                <specular>1.0 0.0 0.0 1</specular>
            </material>
        </visual>
        <collision name='collision'>
            <geometry>
                <cylinder>
                    <radius>0.8</radius>
                    <length>0.4</length>
                </cylinder>
            </geometry>
        </collision>
      </link>
      <link name="right_wheel">
        <pose relative_to="chassis">0 -1.3 -1.2 -1.5707 0 0</pose>
        <visual name='visual'>
            <geometry>
                <cylinder>
                    <radius>0.8</radius>
                    <length>0.4</length>
                </cylinder>
            </geometry>
            <material>
                <ambient>1.0 0.0 0.0 1</ambient>
                <diffuse>1.0 0.0 0.0 1</diffuse>
                <specular>1.0 0.0 0.0 1</specular>
            </material>
        </visual>
        <collision name='collision'>
            <geometry>
                <cylinder>
                    <radius>0.8</radius>
                    <length>0.4</length>
                </cylinder>
            </geometry>
        </collision>
      </link>

      <joint name="left_wheel_joint" type="revolute">
        <pose relative_to="left_wheel"/>
        <parent>chassis</parent>
        <child>left_wheel</child>
        <axis>
            <xyz expressed_in='__model__'>0 1 0</xyz> <!--can be defined as any frame or even arbitrary frames-->
            <limit>
                <lower>-1.79769e+308</lower>    <!--negative infinity-->
                <upper>1.79769e+308</upper>     <!--positive infinity-->
            </limit>
        </axis>
      </joint>
      <joint name='right_wheel_joint' type='revolute'>
          <pose relative_to='right_wheel'/>
          <parent>chassis</parent>
          <child>right_wheel</child>
          <axis>
              <xyz expressed_in='__model__'>0 1 0</xyz>
              <limit>
                  <lower>-1.79769e+308</lower>    <!--negative infinity-->
                  <upper>1.79769e+308</upper>     <!--positive infinity-->
              </limit>
          </axis>
      </joint>

      <frame name = "caster_frame_lf" attached_to="chassis">
        <pose>1.2 0.9 -1.7 0 0 0</pose>
      </frame>
      <link name="caster_wheel_lf">
        <pose relative_to="caster_frame_lf"/>
        <visual name='visual'>
            <geometry>
                <sphere>
                    <radius>0.3</radius>
                </sphere>
            </geometry>
            <material>
                <ambient>0.0 1 0.0 1</ambient>
                <diffuse>0.0 1 0.0 1</diffuse>
                <specular>0.0 1 0.0 1</specular>
            </material>
        </visual>
        <collision name='collision'>
            <geometry>
                <sphere>
                    <radius>0.3</radius>
                </sphere>
            </geometry>
        </collision>
      </link>
      <joint name="caster_joint_lf" type="ball">
        <parent>chassis</parent>
        <child>caster_wheel_lf</child>
      </joint>

      <frame name = "caster_frame_rf" attached_to="chassis">
        <pose>1.2 -0.9 -1.7 0 0 0</pose>
      </frame>
      <link name="caster_wheel_rf">
        <pose relative_to="caster_frame_rf"/>
        <visual name='visual'>
            <geometry>
                <sphere>
                    <radius>0.3</radius>
                </sphere>
            </geometry>
            <material>
                <ambient>0.0 1 0.0 1</ambient>
                <diffuse>0.0 1 0.0 1</diffuse>
                <specular>0.0 1 0.0 1</specular>
            </material>
        </visual>
        <collision name='collision'>
            <geometry>
                <sphere>
                    <radius>0.3</radius>
                </sphere>
            </geometry>
        </collision>
      </link>
      <joint name="caster_joint_rf" type="ball">
        <parent>chassis</parent>
        <child>caster_wheel_rf</child>
      </joint>

      <frame name = "caster_frame_lb" attached_to="chassis">
        <pose>-1.2 0.9 -1.7 0 0 0</pose>
      </frame>
      <link name="caster_wheel_lb">
        <pose relative_to="caster_frame_lb"/>
        <visual name='visual'>
            <geometry>
                <sphere>
                    <radius>0.3</radius>
                </sphere>
            </geometry>
            <material>
                <ambient>0.0 1 0.0 1</ambient>
                <diffuse>0.0 1 0.0 1</diffuse>
                <specular>0.0 1 0.0 1</specular>
            </material>
        </visual>
        <collision name='collision'>
            <geometry>
                <sphere>
                    <radius>0.3</radius>
                </sphere>
            </geometry>
        </collision>
      </link>
      <joint name="caster_joint_lb" type="ball">
        <parent>chassis</parent>
        <child>caster_wheel_lb</child>
      </joint>

      <frame name = "caster_frame_rb" attached_to="chassis">
        <pose>-1.2 -0.9 -1.7 0 0 0</pose>
      </frame>
      <link name="caster_wheel_rb">
        <pose relative_to="caster_frame_rb"/>
        <visual name='visual'>
            <geometry>
                <sphere>
                    <radius>0.3</radius>
                </sphere>
            </geometry>
            <material>
                <ambient>0.0 1 0.0 1</ambient>
                <diffuse>0.0 1 0.0 1</diffuse>
                <specular>0.0 1 0.0 1</specular>
            </material>
        </visual>
        <collision name='collision'>
            <geometry>
                <sphere>
                    <radius>0.3</radius>
                </sphere>
            </geometry>
        </collision>
      </link>
      <joint name="caster_joint_rb" type="ball">
        <parent>chassis</parent>
        <child>caster_wheel_rb</child>
      </joint>

      <plugin
          filename="libignition-gazebo-diff-drive-system.so"
          name="ignition::gazebo::systems::DiffDrive">
          <left_joint>left_wheel_joint</left_joint>
          <right_joint>right_wheel_joint</right_joint>
          <wheel_separation>2.6</wheel_separation>
          <wheel_radius>0.8</wheel_radius>
          <odom_publish_frequency>1</odom_publish_frequency>
          <topic>cmd_vel</topic>
      </plugin>
    </model>
  </world>
</sdf>